<?xml version="1.0" ?>
<robot name="robot_ros2" xmlns:xacro="http://www.ros.org/wiki/xacro">

<xacro:include filename="$(find robot_ros2_description)/urdf/materials.xacro" />
<xacro:include filename="$(find robot_ros2_description)/urdf/robot_ros2.trans" />
<xacro:include filename="$(find robot_ros2_description)/urdf/robot_ros2.gazebo" />
<link name="base_link">
  <inertial>
    <origin xyz="0.0038316835826581247 -5.169769078926864e-17 0.0527909364115352" rpy="0 0 0"/>
    <mass value="2.5079952838369883"/>
    <inertia ixx="0.008146" iyy="0.008711" izz="0.015215" ixy="-0.0" iyz="-0.0" ixz="-0.000361"/>
  </inertial>
  <visual>
    <origin xyz="0 0 0" rpy="0 0 0"/>
    <geometry>
      <mesh filename="file://$(find robot_ros2_description)/meshes/base_link.stl" scale="0.001 0.001 0.001"/>
    </geometry>
    <material name="silver"/>
  </visual>
  <collision>
    <origin xyz="0 0 0" rpy="0 0 0"/>
    <geometry>
      <mesh filename="file://$(find robot_ros2_description)/meshes/base_link.stl" scale="0.001 0.001 0.001"/>
    </geometry>
  </collision>
</link>

<link name="lidar_1">
  <inertial>
    <origin xyz="6.938893903907228e-18 0.0 0.012463876662860945" rpy="0 0 0"/>
    <mass value="0.13237101068556234"/>
    <inertia ixx="4.7e-05" iyy="4.7e-05" izz="8.1e-05" ixy="0.0" iyz="0.0" ixz="0.0"/>
  </inertial>
  <visual>
    <origin xyz="-0.05 -0.0 -0.11" rpy="0 0 0"/>
    <geometry>
      <mesh filename="file://$(find robot_ros2_description)/meshes/lidar_1.stl" scale="0.001 0.001 0.001"/>
    </geometry>
    <material name="silver"/>
  </visual>
  <collision>
    <origin xyz="-0.05 -0.0 -0.11" rpy="0 0 0"/>
    <geometry>
      <mesh filename="file://$(find robot_ros2_description)/meshes/lidar_1.stl" scale="0.001 0.001 0.001"/>
    </geometry>
  </collision>
</link>

<link name="RightWeel_1">
  <inertial>
    <origin xyz="1.3110635570874062e-17 -0.011226303439366023 3.7252903539730653e-10" rpy="0 0 0"/>
    <mass value="0.16128700780301555"/>
    <inertia ixx="0.000113" iyy="0.000212" izz="0.000113" ixy="-0.0" iyz="0.0" ixz="0.0"/>
  </inertial>
  <visual>
    <origin xyz="-0.0 0.1 -0.05" rpy="0 0 0"/>
    <geometry>
      <mesh filename="file://$(find robot_ros2_description)/meshes/RightWeel_1.stl" scale="0.001 0.001 0.001"/>
    </geometry>
    <material name="silver"/>
  </visual>
  <collision>
    <origin xyz="-0.0 0.1 -0.05" rpy="0 0 0"/>
    <geometry>
      <mesh filename="file://$(find robot_ros2_description)/meshes/RightWeel_1.stl" scale="0.001 0.001 0.001"/>
    </geometry>
  </collision>
</link>

<link name="LeftWeel_1">
  <inertial>
    <origin xyz="3.9331906712622195e-17 0.011226303439366023 3.7252905621398824e-10" rpy="0 0 0"/>
    <mass value="0.16128700780301553"/>
    <inertia ixx="0.000113" iyy="0.000212" izz="0.000113" ixy="0.0" iyz="0.0" ixz="0.0"/>
  </inertial>
  <visual>
    <origin xyz="-0.0 -0.1 -0.05" rpy="0 0 0"/>
    <geometry>
      <mesh filename="file://$(find robot_ros2_description)/meshes/LeftWeel_1.stl" scale="0.001 0.001 0.001"/>
    </geometry>
    <material name="silver"/>
  </visual>
  <collision>
    <origin xyz="-0.0 -0.1 -0.05" rpy="0 0 0"/>
    <geometry>
      <mesh filename="file://$(find robot_ros2_description)/meshes/LeftWeel_1.stl" scale="0.001 0.001 0.001"/>
    </geometry>
  </collision>
</link>

<joint name="Rigid 4" type="fixed">
  <origin xyz="0.05 0.0 0.11" rpy="0 0 0"/>
  <parent link="base_link"/>
  <child link="lidar_1"/>
</joint>

<joint name="Revolute 5" type="continuous">
  <origin xyz="0.0 -0.1 0.05" rpy="0 0 0"/>
  <parent link="base_link"/>
  <child link="RightWeel_1"/>
  <axis xyz="0.0 -1.0 0.0"/>
</joint>

<joint name="Revolute 6" type="continuous">
  <origin xyz="0.0 0.1 0.05" rpy="0 0 0"/>
  <parent link="base_link"/>
  <child link="LeftWeel_1"/>
  <axis xyz="0.0 1.0 0.0"/>
</joint>

</robot>
